Workbook

Sheet Dashboard
A1: E-Commerce Business Analytics Dashboard
A2: Portfolio-ready project: sales, customer, delivery, review, and business recommendations
A4: ="Total Revenue"&CHAR(10)&TEXT(KPI_Data!B2,"#,##0.00") -> Total Revenue 17,900,525.67 | D4: ="Delivered Orders"&CHAR(10)&TEXT(KPI_Data!B3,"#,##0") -> Delivered Orders 96,551 | G4: ="Avg Order Value"&CHAR(10)&TEXT(KPI_Data!B5,"#,##0.00") -> Avg Order Value 185.40 | J4: ="Avg Review Score"&CHAR(10)&TEXT(KPI_Data!B6,"0.00") -> Avg Review Score 3.83
A8: ="Late Delivery Rate"&CHAR(10)&TEXT(KPI_Data!B7,"0.0%") -> Late Delivery Rate 24.2% | D8: ="Avg Delivery Days"&CHAR(10)&TEXT(KPI_Data!B8,"0.00") -> Avg Delivery Days 9.15 | G8: ="Unique Customers"&CHAR(10)&TEXT(KPI_Data!B4,"#,##0") -> Unique Customers 96,551 | J8: ="Top State"&CHAR(10)&KPI_Data!B9 -> Top State SP
A12: Key Insights & Business Recommendations
A13: 1. Revenue is concentrated in a few high-performing categories, led by computers_accessories, watches_gifts, and health_beauty.
A14: 2. Late delivery is strongly related to lower review scores; orders with review score 1-3 show materially higher late delivery rates.
A15: 3. SP, RJ, and MG generate the majority of revenue, making them priority markets for logistics and marketing optimization.
A16: 4. Recommended action: monitor seller SLA, prioritize high-revenue categories with better fulfillment quality, and track late delivery weekly.

Sheet KPI_Data
A1: metric | B1: value
A2: Total Revenue | B2: =SUM(Data_Monthly!B2:B25) -> 17900526
A3: Delivered Orders | B3: =SUM(Data_Monthly!C2:C25) -> 96551
A4: Unique Customers | B4: =SUM(Data_Monthly!D2:D25) -> 96551
A5: Average Order Value | B5: =B2/B3 -> 185.39969
A6: Average Review Score | B6: =SUMPRODUCT(Data_Monthly!E2:E25,Data_Monthly!C2:C25)/SUM(Data_Monthly!C2:C25) -> 3.8328231
A7: Late Delivery Rate | B7: =SUMPRODUCT(Data_Monthly!F2:F25,Data_Monthly!C2:C25)/SUM(Data_Monthly!C2:C25) -> 0.24214159
A8: Average Delivery Days | B8: =SUMPRODUCT(Data_State!E2:E28,Data_State!C2:C28)/SUM(Data_State!C2:C28) -> 9.1498097
A9: Top State (by Revenue) | B9: =INDEX(Data_State!A2:A28,MATCH(MAX(Data_State!B2:B28),Data_State!B2:B28,0)) -> SP
A11: All values are live formulas referencing Data_Monthly / Data_State (imported from Python-cleaned exports). Nothing here is pasted manually.

Sheet Monthly_Revenue
A1: order_month | B1: revenue | C1: total_orders | D1: total_customers | E1: avg_review_score | F1: late_delivery_rate | G1: aov | H1: MoM Growth % | I1: Cumulative Revenue
A2: =Data_Monthly!A2 -> 2016-09 | B2: =Data_Monthly!B2 -> 24367.4 | C2: =Data_Monthly!C2 -> 120 | D2: =Data_Monthly!D2 -> 120 | E2: =Data_Monthly!E2 -> 3.5070423 | F2: =Data_Monthly!F2 -> 0.28873239 | G2: =B2/C2 -> 203.06167 | I2: =B2 -> 24367.4
A3: =Data_Monthly!A3 -> 2016-10 | B3: =Data_Monthly!B3 -> 79530.25 | C3: =Data_Monthly!C3 -> 430 | D3: =Data_Monthly!D3 -> 430 | E3: =Data_Monthly!E3 -> 3.7534791 | F3: =Data_Monthly!F3 -> 0.26441352 | G3: =B3/C3 -> 184.95407 | H3: =IFERROR((B3-B2)/B2,"") -> 2.2637971 | I3: =I2+B3 -> 103897.65
A4: =Data_Monthly!A4 -> 2016-11 | B4: =Data_Monthly!B4 -> 143085.49 | C4: =Data_Monthly!C4 -> 755 | D4: =Data_Monthly!D4 -> 755 | E4: =Data_Monthly!E4 -> 3.8957617 | F4: =Data_Monthly!F4 -> 0.22565865 | G4: =B4/C4 -> 189.51721 | H4: =IFERROR((B4-B3)/B3,"") -> 0.79913291 | I4: =I3+B4 -> 246983.14
A5: =Data_Monthly!A5 -> 2016-12 | B5: =Data_Monthly!B5 -> 216396.36 | C5: =Data_Monthly!C5 -> 1160 | D5: =Data_Monthly!D5 -> 1160 | E5: =Data_Monthly!E5 -> 3.85693 | F5: =Data_Monthly!F5 -> 0.2414307 | G5: =B5/C5 -> 186.54859 | H5: =IFERROR((B5-B4)/B4,"") -> 0.51235712 | I5: =I4+B5 -> 463379.5
A6: =Data_Monthly!A6 -> 2017-01 | B6: =Data_Monthly!B6 -> 289073.93 | C6: =Data_Monthly!C6 -> 1591 | D6: =Data_Monthly!D6 -> 1591 | E6: =Data_Monthly!E6 -> 3.8638111 | F6: =Data_Monthly!F6 -> 0.24437122 | G6: =B6/C6 -> 181.69323 | H6: =IFERROR((B6-B5)/B5,"") -> 0.33585394 | I6: =I5+B6 -> 752453.43
A7: =Data_Monthly!A7 -> 2017-02 | B7: =Data_Monthly!B7 -> 339718.38 | C7: =Data_Monthly!C7 -> 1851 | D7: =Data_Monthly!D7 -> 1851 | E7: =Data_Monthly!E7 -> 3.822054 | F7: =Data_Monthly!F7 -> 0.24372929 | G7: =B7/C7 -> 183.53235 | H7: =IFERROR((B7-B6)/B6,"") -> 0.17519549 | I7: =I6+B7 -> 1092171.8
A8: =Data_Monthly!A8 -> 2017-03 | B8: =Data_Monthly!B8 -> 438741.8 | C8: =Data_Monthly!C8 -> 2435 | D8: =Data_Monthly!D8 -> 2435 | E8: =Data_Monthly!E8 -> 3.8461263 | F8: =Data_Monthly!F8 -> 0.23637016 | G8: =B8/C8 -> 180.18144 | H8: =IFERROR((B8-B7)/B7,"") -> 0.29148679 | I8: =I7+B8 -> 1530913.6
A9: =Data_Monthly!A9 -> 2017-04 | B9: =Data_Monthly!B9 -> 509440.18 | C9: =Data_Monthly!C9 -> 2744 | D9: =Data_Monthly!D9 -> 2744 | E9: =Data_Monthly!E9 -> 3.8177511 | F9: =Data_Monthly!F9 -> 0.25300063 | G9: =B9/C9 -> 185.65604 | H9: =IFERROR((B9-B8)/B8,"") -> 0.16113892 | I9: =I8+B9 -> 2040353.8
A10: =Data_Monthly!A10 -> 2017-05 | B10: =Data_Monthly!B10 -> 582457 | C10: =Data_Monthly!C10 -> 3129 | D10: =Data_Monthly!D10 -> 3129 | E10: =Data_Monthly!E10 -> 3.8468493 | F10: =Data_Monthly!F10 -> 0.2369863 | G10: =B10/C10 -> 186.14797 | H10: =IFERROR((B10-B9)/B9,"") -> 0.14332756 | I10: =I9+B10 -> 2622810.8
A11: =Data_Monthly!A11 -> 2017-06 | B11: =Data_Monthly!B11 -> 636554.15 | C11: =Data_Monthly!C11 -> 3457 | D11: =Data_Monthly!D11 -> 3457 | E11: =Data_Monthly!E11 -> 3.8385155 | F11: =Data_Monthly!F11 -> 0.24147442 | G11: =B11/C11 -> 184.13484 | H11: =IFERROR((B11-B10)/B10,"") -> 0.0928775 | I11: =I10+B11 -> 3259364.9
A12: =Data_Monthly!A12 -> 2017-07 | B12: =Data_Monthly!B12 -> 746312.1 | C12: =Data_Monthly!C12 -> 3960 | D12: =Data_Monthly!D12 -> 3960 | E12: =Data_Monthly!E12 -> 3.8176663 | F12: =Data_Monthly!F12 -> 0.23642312 | G12: =B12/C12 -> 188.46265 | H12: =IFERROR((B12-B11)/B11,"") -> 0.17242516 | I12: =I11+B12 -> 4005677
A13: =Data_Monthly!A13 -> 2017-08 | B13: =Data_Monthly!B13 -> 786994.01 | C13: =Data_Monthly!C13 -> 4302 | D13: =Data_Monthly!D13 -> 4302 | E13: =Data_Monthly!E13 -> 3.8611336 | F13: =Data_Monthly!F13 -> 0.23805668 | G13: =B13/C13 -> 182.93678 | H13: =IFERROR((B13-B12)/B12,"") -> 0.054510586 | I13: =I12+B13 -> 4792671
A14: =Data_Monthly!A14 -> 2017-09 | B14: =Data_Monthly!B14 -> 862952.5 | C14: =Data_Monthly!C14 -> 4621 | D14: =Data_Monthly!D14 -> 4621 | E14: =Data_Monthly!E14 -> 3.8206379 | F14: =Data_Monthly!F14 -> 0.24146341 | G14: =B14/C14 -> 186.74583 | H14: =IFERROR((B14-B13)/B13,"") -> 0.09651724 | I14: =I13+B14 -> 5655623.5
... A25: =Data_Monthly!A25 -> 2018-08 | B25: =Data_Monthly!B25 -> 962267.57 | C25: =Data_Monthly!C25 -> 5095 | D25: =Data_Monthly!D25 -> 5095 | E25: =Data_Monthly!E25 -> 3.8342336 | F25: =Data_Monthly!F25 -> 0.24155976 | G25: =B25/C25 -> 188.86508 | H25: =IFERROR((B25-B24)/B24,"") -> -0.16826183 | I25: =I24+B25 -> 17900526
A27: Values pulled live from Data_Monthly; AOV, MoM growth, and cumulative revenue are calculated with formulas, not pasted.

Sheet Category_Analysis
A1: product_category_name_english | B1: revenue | C1: total_orders | D1: total_items | E1: avg_price | F1: avg_freight | G1: avg_review_score | H1: late_delivery_rate | I1: % of Total Revenue | J1: Rank
A2: =INDEX(Data_Category!$A$2:$A$26,MATCH(B2,Data_Category!$B$2:$B$26,0)) -> computers_accessories | B2: =LARGE(Data_Category!$B$2:$B$26,1) -> 1685925.4 | C2: =INDEX(Data_Category!$C$2:$C$26,MATCH($A2,Data_Category!$A$2:$A$26,0)) -> 7507 | D2: =INDEX(Data_Category!$D$2:$D$26,MATCH($A2,Data_Category!$A$2:$A$26,0)) -> 7589 | E2: =INDEX(Data_Category!$E$2:$E$26,MATCH($A2,Data_Category!$A$2:$A$26,0)) -> 200.76994 | F2: =INDEX(Data_Category!$F$2:$F$26,MATCH($A2,Data_Category!$A$2:$A$26,0)) -> 21.383892 | G2: =INDEX(Data_Category!$G$2:$G$26,MATCH($A2,Data_Category!$A$2:$A$26,0)) -> 3.8348926 | H2: =INDEX(Data_Category!$H$2:$H$26,MATCH($A2,Data_Category!$A$2:$A$26,0)) -> 0.24232442 | I2: =B2/SUM(Data_Category!$B$2:$B$26) -> 0.094183012 | J2: =RANK(B2,Data_Category!$B$2:$B$26) -> 1
A3: =INDEX(Data_Category!$A$2:$A$26,MATCH(B3,Data_Category!$B$2:$B$26,0)) -> watches_gifts | B3: =LARGE(Data_Category!$B$2:$B$26,2) -> 1508123.3 | C3: =INDEX(Data_Category!$C$2:$C$26,MATCH($A3,Data_Category!$A$2:$A$26,0)) -> 5907 | D3: =INDEX(Data_Category!$D$2:$D$26,MATCH($A3,Data_Category!$A$2:$A$26,0)) -> 5957 | E3: =INDEX(Data_Category!$E$2:$E$26,MATCH($A3,Data_Category!$A$2:$A$26,0)) -> 230.46382 | F3: =INDEX(Data_Category!$F$2:$F$26,MATCH($A3,Data_Category!$A$2:$A$26,0)) -> 22.704428 | G3: =INDEX(Data_Category!$G$2:$G$26,MATCH($A3,Data_Category!$A$2:$A$26,0)) -> 3.8341447 | H3: =INDEX(Data_Category!$H$2:$H$26,MATCH($A3,Data_Category!$A$2:$A$26,0)) -> 0.24223602 | I3: =B3/SUM(Data_Category!$B$2:$B$26) -> 0.084250223 | J3: =RANK(B3,Data_Category!$B$2:$B$26) -> 2
A4: =INDEX(Data_Category!$A$2:$A$26,MATCH(B4,Data_Category!$B$2:$B$26,0)) -> health_beauty | B4: =LARGE(Data_Category!$B$2:$B$26,3) -> 1432652.7 | C4: =INDEX(Data_Category!$C$2:$C$26,MATCH($A4,Data_Category!$A$2:$A$26,0)) -> 9399 | D4: =INDEX(Data_Category!$D$2:$D$26,MATCH($A4,Data_Category!$A$2:$A$26,0)) -> 9536 | E4: =INDEX(Data_Category!$E$2:$E$26,MATCH($A4,Data_Category!$A$2:$A$26,0)) -> 131.9781 | F4: =INDEX(Data_Category!$F$2:$F$26,MATCH($A4,Data_Category!$A$2:$A$26,0)) -> 18.258132 | G4: =INDEX(Data_Category!$G$2:$G$26,MATCH($A4,Data_Category!$A$2:$A$26,0)) -> 3.8464765 | H4: =INDEX(Data_Category!$H$2:$H$26,MATCH($A4,Data_Category!$A$2:$A$26,0)) -> 0.2457005 | I4: =B4/SUM(Data_Category!$B$2:$B$26) -> 0.080034113 | J4: =RANK(B4,Data_Category!$B$2:$B$26) -> 3
A5: =INDEX(Data_Category!$A$2:$A$26,MATCH(B5,Data_Category!$B$2:$B$26,0)) -> furniture_decor | B5: =LARGE(Data_Category!$B$2:$B$26,4) -> 1424562.9 | C5: =INDEX(Data_Category!$C$2:$C$26,MATCH($A5,Data_Category!$A$2:$A$26,0)) -> 7570 | D5: =INDEX(Data_Category!$D$2:$D$26,MATCH($A5,Data_Category!$A$2:$A$26,0)) -> 7672 | E5: =INDEX(Data_Category!$E$2:$E$26,MATCH($A5,Data_Category!$A$2:$A$26,0)) -> 165.93068 | F5: =INDEX(Data_Category!$F$2:$F$26,MATCH($A5,Data_Category!$A$2:$A$26,0)) -> 19.752694 | G5: =INDEX(Data_Category!$G$2:$G$26,MATCH($A5,Data_Category!$A$2:$A$26,0)) -> 3.830683 | H5: =INDEX(Data_Category!$H$2:$H$26,MATCH($A5,Data_Category!$A$2:$A$26,0)) -> 0.24973931 | I5: =B5/SUM(Data_Category!$B$2:$B$26) -> 0.079582181 | J5: =RANK(B5,Data_Category!$B$2:$B$26) -> 4
A6: =INDEX(Data_Category!$A$2:$A$26,MATCH(B6,Data_Category!$B$2:$B$26,0)) -> sports_leisure | B6: =LARGE(Data_Category!$B$2:$B$26,5) -> 1273178.4 | C6: =INDEX(Data_Category!$C$2:$C$26,MATCH($A6,Data_Category!$A$2:$A$26,0)) -> 8590 | D6: =INDEX(Data_Category!$D$2:$D$26,MATCH($A6,Data_Category!$A$2:$A$26,0)) -> 8710 | E6: =INDEX(Data_Category!$E$2:$E$26,MATCH($A6,Data_Category!$A$2:$A$26,0)) -> 127.97638 | F6: =INDEX(Data_Category!$F$2:$F$26,MATCH($A6,Data_Category!$A$2:$A$26,0)) -> 18.197953 | G6: =INDEX(Data_Category!$G$2:$G$26,MATCH($A6,Data_Category!$A$2:$A$26,0)) -> 3.8061998 | H6: =INDEX(Data_Category!$H$2:$H$26,MATCH($A6,Data_Category!$A$2:$A$26,0)) -> 0.24948335 | I6: =B6/SUM(Data_Category!$B$2:$B$26) -> 0.071125198 | J6: =RANK(B6,Data_Category!$B$2:$B$26) -> 5
A7: =INDEX(Data_Category!$A$2:$A$26,MATCH(B7,Data_Category!$B$2:$B$26,0)) -> bed_bath_table | B7: =LARGE(Data_Category!$B$2:$B$26,6) -> 1214319.1 | C7: =INDEX(Data_Category!$C$2:$C$26,MATCH($A7,Data_Category!$A$2:$A$26,0)) -> 10297 | D7: =INDEX(Data_Category!$D$2:$D$26,MATCH($A7,Data_Category!$A$2:$A$26,0)) -> 10440 | E7: =INDEX(Data_Category!$E$2:$E$26,MATCH($A7,Data_Category!$A$2:$A$26,0)) -> 99.512131 | F7: =INDEX(Data_Category!$F$2:$F$26,MATCH($A7,Data_Category!$A$2:$A$26,0)) -> 16.801962 | G7: =INDEX(Data_Category!$G$2:$G$26,MATCH($A7,Data_Category!$A$2:$A$26,0)) -> 3.8427203 | H7: =INDEX(Data_Category!$H$2:$H$26,MATCH($A7,Data_Category!$A$2:$A$26,0)) -> 0.24272031 | I7: =B7/SUM(Data_Category!$B$2:$B$26) -> 0.067837065 | J7: =RANK(B7,Data_Category!$B$2:$B$26) -> 6
A8: =INDEX(Data_Category!$A$2:$A$26,MATCH(B8,Data_Category!$B$2:$B$26,0)) -> electronics | B8: =LARGE(Data_Category!$B$2:$B$26,7) -> 928428.79 | C8: =INDEX(Data_Category!$C$2:$C$26,MATCH($A8,Data_Category!$A$2:$A$26,0)) -> 3510 | D8: =INDEX(Data_Category!$D$2:$D$26,MATCH($A8,Data_Category!$A$2:$A$26,0)) -> 3528 | E8: =INDEX(Data_Category!$E$2:$E$26,MATCH($A8,Data_Category!$A$2:$A$26,0)) -> 240.02299 | F8: =INDEX(Data_Category!$F$2:$F$26,MATCH($A8,Data_Category!$A$2:$A$26,0)) -> 23.137098 | G8: =INDEX(Data_Category!$G$2:$G$26,MATCH($A8,Data_Category!$A$2:$A$26,0)) -> 3.86678 | H8: =INDEX(Data_Category!$H$2:$H$26,MATCH($A8,Data_Category!$A$2:$A$26,0)) -> 0.23922902 | I8: =B8/SUM(Data_Category!$B$2:$B$26) -> 0.051866007 | J8: =RANK(B8,Data_Category!$B$2:$B$26) -> 7
A9: =INDEX(Data_Category!$A$2:$A$26,MATCH(B9,Data_Category!$B$2:$B$26,0)) -> garden_tools | B9: =LARGE(Data_Category!$B$2:$B$26,8) -> 865718.48 | C9: =INDEX(Data_Category!$C$2:$C$26,MATCH($A9,Data_Category!$A$2:$A$26,0)) -> 5291 | D9: =INDEX(Data_Category!$D$2:$D$26,MATCH($A9,Data_Category!$A$2:$A$26,0)) -> 5328 | E9: =INDEX(Data_Category!$E$2:$E$26,MATCH($A9,Data_Category!$A$2:$A$26,0)) -> 143.78362 | F9: =INDEX(Data_Category!$F$2:$F$26,MATCH($A9,Data_Category!$A$2:$A$26,0)) -> 18.701077 | G9: =INDEX(Data_Category!$G$2:$G$26,MATCH($A9,Data_Category!$A$2:$A$26,0)) -> 3.8209459 | H9: =INDEX(Data_Category!$H$2:$H$26,MATCH($A9,Data_Category!$A$2:$A$26,0)) -> 0.2454955 | I9: =B9/SUM(Data_Category!$B$2:$B$26) -> 0.048362741 | J9: =RANK(B9,Data_Category!$B$2:$B$26) -> 8
A10: =INDEX(Data_Category!$A$2:$A$26,MATCH(B10,Data_Category!$B$2:$B$26,0)) -> auto | B10: =LARGE(Data_Category!$B$2:$B$26,9) -> 858355.87 | C10: =INDEX(Data_Category!$C$2:$C$26,MATCH($A10,Data_Category!$A$2:$A$26,0)) -> 4647 | D10: =INDEX(Data_Category!$D$2:$D$26,MATCH($A10,Data_Category!$A$2:$A$26,0)) -> 4681 | E10: =INDEX(Data_Category!$E$2:$E$26,MATCH($A10,Data_Category!$A$2:$A$26,0)) -> 163.61384 | F10: =INDEX(Data_Category!$F$2:$F$26,MATCH($A10,Data_Category!$A$2:$A$26,0)) -> 19.756351 | G10: =INDEX(Data_Category!$G$2:$G$26,MATCH($A10,Data_Category!$A$2:$A$26,0)) -> 3.8397778 | H10: =INDEX(Data_Category!$H$2:$H$26,MATCH($A10,Data_Category!$A$2:$A$26,0)) -> 0.23435163 | I10: =B10/SUM(Data_Category!$B$2:$B$26) -> 0.047951434 | J10: =RANK(B10,Data_Category!$B$2:$B$26) -> 9
A11: =INDEX(Data_Category!$A$2:$A$26,MATCH(B11,Data_Category!$B$2:$B$26,0)) -> cool_stuff | B11: =LARGE(Data_Category!$B$2:$B$26,10) -> 810594.84 | C11: =INDEX(Data_Category!$C$2:$C$26,MATCH($A11,Data_Category!$A$2:$A$26,0)) -> 4086 | D11: =INDEX(Data_Category!$D$2:$D$26,MATCH($A11,Data_Category!$A$2:$A$26,0)) -> 4109 | E11: =INDEX(Data_Category!$E$2:$E$26,MATCH($A11,Data_Category!$A$2:$A$26,0)) -> 177.0273 | F11: =INDEX(Data_Category!$F$2:$F$26,MATCH($A11,Data_Category!$A$2:$A$26,0)) -> 20.245722 | G11: =INDEX(Data_Category!$G$2:$G$26,MATCH($A11,Data_Category!$A$2:$A$26,0)) -> 3.8352397 | H11: =INDEX(Data_Category!$H$2:$H$26,MATCH($A11,Data_Category!$A$2:$A$26,0)) -> 0.2411779 | I11: =B11/SUM(Data_Category!$B$2:$B$26) -> 0.045283298 | J11: =RANK(B11,Data_Category!$B$2:$B$26) -> 10
A12: =INDEX(Data_Category!$A$2:$A$26,MATCH(B12,Data_Category!$B$2:$B$26,0)) -> housewares | B12: =LARGE(Data_Category!$B$2:$B$26,11) -> 717020.21 | C12: =INDEX(Data_Category!$C$2:$C$26,MATCH($A12,Data_Category!$A$2:$A$26,0)) -> 7160 | D12: =INDEX(Data_Category!$D$2:$D$26,MATCH($A12,Data_Category!$A$2:$A$26,0)) -> 7230 | E12: =INDEX(Data_Category!$E$2:$E$26,MATCH($A12,Data_Category!$A$2:$A$26,0)) -> 83.114823 | F12: =INDEX(Data_Category!$F$2:$F$26,MATCH($A12,Data_Category!$A$2:$A$26,0)) -> 16.058097 | G12: =INDEX(Data_Category!$G$2:$G$26,MATCH($A12,Data_Category!$A$2:$A$26,0)) -> 3.8127248 | H12: =INDEX(Data_Category!$H$2:$H$26,MATCH($A12,Data_Category!$A$2:$A$26,0)) -> 0.23941909 | I12: =B12/SUM(Data_Category!$B$2:$B$26) -> 0.040055819 | J12: =RANK(B12,Data_Category!$B$2:$B$26) -> 11
A13: =INDEX(Data_Category!$A$2:$A$26,MATCH(B13,Data_Category!$B$2:$B$26,0)) -> office_furniture | B13: =LARGE(Data_Category!$B$2:$B$26,12) -> 707103.23 | C13: =INDEX(Data_Category!$C$2:$C$26,MATCH($A13,Data_Category!$A$2:$A$26,0)) -> 2311 | D13: =INDEX(Data_Category!$D$2:$D$26,MATCH($A13,Data_Category!$A$2:$A$26,0)) -> 2323 | E13: =INDEX(Data_Category!$E$2:$E$26,MATCH($A13,Data_Category!$A$2:$A$26,0)) -> 279.42672 | F13: =INDEX(Data_Category!$F$2:$F$26,MATCH($A13,Data_Category!$A$2:$A$26,0)) -> 24.965549 | G13: =INDEX(Data_Category!$G$2:$G$26,MATCH($A13,Data_Category!$A$2:$A$26,0)) -> 3.8286698 | H13: =INDEX(Data_Category!$H$2:$H$26,MATCH($A13,Data_Category!$A$2:$A$26,0)) -> 0.23590185 | I13: =B13/SUM(Data_Category!$B$2:$B$26) -> 0.039501814 | J13: =RANK(B13,Data_Category!$B$2:$B$26) -> 12
A14: =INDEX(Data_Category!$A$2:$A$26,MATCH(B14,Data_Category!$B$2:$B$26,0)) -> telephony | B14: =LARGE(Data_Category!$B$2:$B$26,13) -> 673721.88 | C14: =INDEX(Data_Category!$C$2:$C$26,MATCH($A14,Data_Category!$A$2:$A$26,0)) -> 5734 | D14: =INDEX(Data_Category!$D$2:$D$26,MATCH($A14,Data_Category!$A$2:$A$26,0)) -> 5789 | E14: =INDEX(Data_Category!$E$2:$E$26,MATCH($A14,Data_Category!$A$2:$A$26,0)) -> 99.575894 | F14: =INDEX(Data_Category!$F$2:$F$26,MATCH($A14,Data_Category!$A$2:$A$26,0)) -> 16.803771 | G14: =INDEX(Data_Category!$G$2:$G$26,MATCH($A14,Data_Category!$A$2:$A$26,0)) -> 3.8695802 | H14: =INDEX(Data_Category!$H$2:$H$26,MATCH($A14,Data_Category!$A$2:$A$26,0)) -> 0.2361375 | I14: =B14/SUM(Data_Category!$B$2:$B$26) -> 0.037636989 | J14: =RANK(B14,Data_Category!$B$2:$B$26) -> 13
A15: =INDEX(Data_Category!$A$2:$A$26,MATCH(B15,Data_Category!$B$2:$B$26,0)) -> toys | B15: =LARGE(Data_Category!$B$2:$B$26,14) -> 516803.33 | C15: =INDEX(Data_Category!$C$2:$C$26,MATCH($A15,Data_Category!$A$2:$A$26,0)) -> 4666 | D15: =INDEX(Data_Category!$D$2:$D$26,MATCH($A15,Data_Category!$A$2:$A$26,0)) -> 4690 | E15: =INDEX(Data_Category!$E$2:$E$26,MATCH($A15,Data_Category!$A$2:$A$26,0)) -> 93.690834 | F15: =INDEX(Data_Category!$F$2:$F$26,MATCH($A15,Data_Category!$A$2:$A$26,0)) -> 16.501774 | G15: =INDEX(Data_Category!$G$2:$G$26,MATCH($A15,Data_Category!$A$2:$A$26,0)) -> 3.849467 | H15: =INDEX(Data_Category!$H$2:$H$26,MATCH($A15,Data_Category!$A$2:$A$26,0)) -> 0.23880597 | I15: =B15/SUM(Data_Category!$B$2:$B$26) -> 0.028870847 | J15: =RANK(B15,Data_Category!$B$2:$B$26) -> 14
A16: =INDEX(Data_Category!$A$2:$A$26,MATCH(B16,Data_Category!$B$2:$B$26,0)) -> home_appliances | B16: =LARGE(Data_Category!$B$2:$B$26,15) -> 510853.57 | C16: =INDEX(Data_Category!$C$2:$C$26,MATCH($A16,Data_Category!$A$2:$A$26,0)) -> 1617 | D16: =INDEX(Data_Category!$D$2:$D$26,MATCH($A16,Data_Category!$A$2:$A$26,0)) -> 1622 | E16: =INDEX(Data_Category!$E$2:$E$26,MATCH($A16,Data_Category!$A$2:$A$26,0)) -> 289.46669 | F16: =INDEX(Data_Category!$F$2:$F$26,MATCH($A16,Data_Category!$A$2:$A$26,0)) -> 25.48619 | G16: =INDEX(Data_Category!$G$2:$G$26,MATCH($A16,Data_Category!$A$2:$A$26,0)) -> 3.8403206 | H16: =INDEX(Data_Category!$H$2:$H$26,MATCH($A16,Data_Category!$A$2:$A$26,0)) -> 0.23427867 | I16: =B16/SUM(Data_Category!$B$2:$B$26) -> 0.028538467 | J16: =RANK(B16,Data_Category!$B$2:$B$26) -> 15
A17: =INDEX(Data_Category!$A$2:$A$26,MATCH(B17,Data_Category!$B$2:$B$26,0)) -> baby | B17: =LARGE(Data_Category!$B$2:$B$26,16) -> 477829.58 | C17: =INDEX(Data_Category!$C$2:$C$26,MATCH($A17,Data_Category!$A$2:$A$26,0)) -> 3381 | D17: =INDEX(Data_Category!$D$2:$D$26,MATCH($A17,Data_Category!$A$2:$A$26,0)) -> 3399 | E17: =INDEX(Data_Category!$E$2:$E$26,MATCH($A17,Data_Category!$A$2:$A$26,0)) -> 122.66582 | F17: =INDEX(Data_Category!$F$2:$F$26,MATCH($A17,Data_Category!$A$2:$A$26,0)) -> 17.913636 | G17: =INDEX(Data_Category!$G$2:$G$26,MATCH($A17,Data_Category!$A$2:$A$26,0)) -> 3.828479 | H17: =INDEX(Data_Category!$H$2:$H$26,MATCH($A17,Data_Category!$A$2:$A$26,0)) -> 0.239188 | I17: =B17/SUM(Data_Category!$B$2:$B$26) -> 0.026693606 | J17: =RANK(B17,Data_Category!$B$2:$B$26) -> 16
A18: =INDEX(Data_Category!$A$2:$A$26,MATCH(B18,Data_Category!$B$2:$B$26,0)) -> perfumery | B18: =LARGE(Data_Category!$B$2:$B$26,17) -> 462015.16 | C18: =INDEX(Data_Category!$C$2:$C$26,MATCH($A18,Data_Category!$A$2:$A$26,0)) -> 3768 | D18: =INDEX(Data_Category!$D$2:$D$26,MATCH($A18,Data_Category!$A$2:$A$26,0)) -> 3794 | E18: =INDEX(Data_Category!$E$2:$E$26,MATCH($A18,Data_Category!$A$2:$A$26,0)) -> 104.6824 | F18: =INDEX(Data_Category!$F$2:$F$26,MATCH($A18,Data_Category!$A$2:$A$26,0)) -> 17.092818 | G18: =INDEX(Data_Category!$G$2:$G$26,MATCH($A18,Data_Category!$A$2:$A$26,0)) -> 3.832894 | H18: =INDEX(Data_Category!$H$2:$H$26,MATCH($A18,Data_Category!$A$2:$A$26,0)) -> 0.24064312 | I18: =B18/SUM(Data_Category!$B$2:$B$26) -> 0.025810145 | J18: =RANK(B18,Data_Category!$B$2:$B$26) -> 17
A19: =INDEX(Data_Category!$A$2:$A$26,MATCH(B19,Data_Category!$B$2:$B$26,0)) -> pet_shop | B19: =LARGE(Data_Category!$B$2:$B$26,18) -> 304219.86 | C19: =INDEX(Data_Category!$C$2:$C$26,MATCH($A19,Data_Category!$A$2:$A$26,0)) -> 2356 | D19: =INDEX(Data_Category!$D$2:$D$26,MATCH($A19,Data_Category!$A$2:$A$26,0)) -> 2363 | E19: =INDEX(Data_Category!$E$2:$E$26,MATCH($A19,Data_Category!$A$2:$A$26,0)) -> 111.3423 | F19: =INDEX(Data_Category!$F$2:$F$26,MATCH($A19,Data_Category!$A$2:$A$26,0)) -> 17.400766 | G19: =INDEX(Data_Category!$G$2:$G$26,MATCH($A19,Data_Category!$A$2:$A$26,0)) -> 3.8197207 | H19: =INDEX(Data_Category!$H$2:$H$26,MATCH($A19,Data_Category!$A$2:$A$26,0)) -> 0.24587389 | I19: =B19/SUM(Data_Category!$B$2:$B$26) -> 0.016995024 | J19: =RANK(B19,Data_Category!$B$2:$B$26) -> 18
A20: =INDEX(Data_Category!$A$2:$A$26,MATCH(B20,Data_Category!$B$2:$B$26,0)) -> fashion_bags_accessories | B20: =LARGE(Data_Category!$B$2:$B$26,19) -> 300384.06 | C20: =INDEX(Data_Category!$C$2:$C$26,MATCH($A20,Data_Category!$A$2:$A$26,0)) -> 2861 | D20: =INDEX(Data_Category!$D$2:$D$26,MATCH($A20,Data_Category!$A$2:$A$26,0)) -> 2874 | E20: =INDEX(Data_Category!$E$2:$E$26,MATCH($A20,Data_Category!$A$2:$A$26,0)) -> 88.278403 | F20: =INDEX(Data_Category!$F$2:$F$26,MATCH($A20,Data_Category!$A$2:$A$26,0)) -> 16.239363 | G20: =INDEX(Data_Category!$G$2:$G$26,MATCH($A20,Data_Category!$A$2:$A$26,0)) -> 3.8350731 | H20: =INDEX(Data_Category!$H$2:$H$26,MATCH($A20,Data_Category!$A$2:$A$26,0)) -> 0.23869172 | I20: =B20/SUM(Data_Category!$B$2:$B$26) -> 0.01678074 | J20: =RANK(B20,Data_Category!$B$2:$B$26) -> 19
A21: =INDEX(Data_Category!$A$2:$A$26,MATCH(B21,Data_Category!$B$2:$B$26,0)) -> luggage_accessories | B21: =LARGE(Data_Category!$B$2:$B$26,20) -> 287343.68 | C21: =INDEX(Data_Category!$C$2:$C$26,MATCH($A21,Data_Category!$A$2:$A$26,0)) -> 1657 | D21: =INDEX(Data_Category!$D$2:$D$26,MATCH($A21,Data_Category!$A$2:$A$26,0)) -> 1662 | E21: =INDEX(Data_Category!$E$2:$E$26,MATCH($A21,Data_Category!$A$2:$A$26,0)) -> 153.63642 | F21: =INDEX(Data_Category!$F$2:$F$26,MATCH($A21,Data_Category!$A$2:$A$26,0)) -> 19.253881 | G21: =INDEX(Data_Category!$G$2:$G$26,MATCH($A21,Data_Category!$A$2:$A$26,0)) -> 3.8261131 | H21: =INDEX(Data_Category!$H$2:$H$26,MATCH($A21,Data_Category!$A$2:$A$26,0)) -> 0.24247894 | I21: =B21/SUM(Data_Category!$B$2:$B$26) -> 0.016052248 | J21: =RANK(B21,Data_Category!$B$2:$B$26) -> 20
A22: =INDEX(Data_Category!$A$2:$A$26,MATCH(B22,Data_Category!$B$2:$B$26,0)) -> audio | B22: =LARGE(Data_Category!$B$2:$B$26,21) -> 260449.72 | C22: =INDEX(Data_Category!$C$2:$C$26,MATCH($A22,Data_Category!$A$2:$A$26,0)) -> 1255 | D22: =INDEX(Data_Category!$D$2:$D$26,MATCH($A22,Data_Category!$A$2:$A$26,0)) -> 1256 | E22: =INDEX(Data_Category!$E$2:$E$26,MATCH($A22,Data_Category!$A$2:$A$26,0)) -> 186.62443 | F22: =INDEX(Data_Category!$F$2:$F$26,MATCH($A22,Data_Category!$A$2:$A$26,0)) -> 20.74 | G22: =INDEX(Data_Category!$G$2:$G$26,MATCH($A22,Data_Category!$A$2:$A$26,0)) -> 3.8073248 | H22: =INDEX(Data_Category!$H$2:$H$26,MATCH($A22,Data_Category!$A$2:$A$26,0)) -> 0.25318471 | I22: =B22/SUM(Data_Category!$B$2:$B$26) -> 0.014549836 | J22: =RANK(B22,Data_Category!$B$2:$B$26) -> 21
A23: =INDEX(Data_Category!$A$2:$A$26,MATCH(B23,Data_Category!$B$2:$B$26,0)) -> stationery | B23: =LARGE(Data_Category!$B$2:$B$26,22) -> 246361.02 | C23: =INDEX(Data_Category!$C$2:$C$26,MATCH($A23,Data_Category!$A$2:$A$26,0)) -> 2991 | D23: =INDEX(Data_Category!$D$2:$D$26,MATCH($A23,Data_Category!$A$2:$A$26,0)) -> 3000 | E23: =INDEX(Data_Category!$E$2:$E$26,MATCH($A23,Data_Category!$A$2:$A$26,0)) -> 66.76855 | F23: =INDEX(Data_Category!$F$2:$F$26,MATCH($A23,Data_Category!$A$2:$A$26,0)) -> 15.35179 | G23: =INDEX(Data_Category!$G$2:$G$26,MATCH($A23,Data_Category!$A$2:$A$26,0)) -> 3.823 | H23: =INDEX(Data_Category!$H$2:$H$26,MATCH($A23,Data_Category!$A$2:$A$26,0)) -> 0.23933333 | I23: =B23/SUM(Data_Category!$B$2:$B$26) -> 0.013762781 | J23: =RANK(B23,Data_Category!$B$2:$B$26) -> 22
A24: =INDEX(Data_Category!$A$2:$A$26,MATCH(B24,Data_Category!$B$2:$B$26,0)) -> musical_instruments | B24: =LARGE(Data_Category!$B$2:$B$26,23) -> 234496.85 | C24: =INDEX(Data_Category!$C$2:$C$26,MATCH($A24,Data_Category!$A$2:$A$26,0)) -> 1003 | D24: =INDEX(Data_Category!$D$2:$D$26,MATCH($A24,Data_Category!$A$2:$A$26,0)) -> 1004 | E24: =INDEX(Data_Category!$E$2:$E$26,MATCH($A24,Data_Category!$A$2:$A$26,0)) -> 211.67331 | F24: =INDEX(Data_Category!$F$2:$F$26,MATCH($A24,Data_Category!$A$2:$A$26,0)) -> 21.889293 | G24: =INDEX(Data_Category!$G$2:$G$26,MATCH($A24,Data_Category!$A$2:$A$26,0)) -> 3.8187251 | H24: =INDEX(Data_Category!$H$2:$H$26,MATCH($A24,Data_Category!$A$2:$A$26,0)) -> 0.24203187 | I24: =B24/SUM(Data_Category!$B$2:$B$26) -> 0.013099998 | J24: =RANK(B24,Data_Category!$B$2:$B$26) -> 23
A25: =INDEX(Data_Category!$A$2:$A$26,MATCH(B25,Data_Category!$B$2:$B$26,0)) -> books_general_interest | B25: =LARGE(Data_Category!$B$2:$B$26,24) -> 150438.55 | C25: =INDEX(Data_Category!$C$2:$C$26,MATCH($A25,Data_Category!$A$2:$A$26,0)) -> 1978 | D25: =INDEX(Data_Category!$D$2:$D$26,MATCH($A25,Data_Category!$A$2:$A$26,0)) -> 1985 | E25: =INDEX(Data_Category!$E$2:$E$26,MATCH($A25,Data_Category!$A$2:$A$26,0)) -> 60.761068 | F25: =INDEX(Data_Category!$F$2:$F$26,MATCH($A25,Data_Category!$A$2:$A$26,0)) -> 15.026615 | G25: =INDEX(Data_Category!$G$2:$G$26,MATCH($A25,Data_Category!$A$2:$A$26,0)) -> 3.786398 | H25: =INDEX(Data_Category!$H$2:$H$26,MATCH($A25,Data_Category!$A$2:$A$26,0)) -> 0.23526448 | I25: =B25/SUM(Data_Category!$B$2:$B$26) -> 0.0084041415 | J25: =RANK(B25,Data_Category!$B$2:$B$26) -> 24
A26: =INDEX(Data_Category!$A$2:$A$26,MATCH(B26,Data_Category!$B$2:$B$26,0)) -> food | B26: =LARGE(Data_Category!$B$2:$B$26,25) -> 49625.13 | C26: =INDEX(Data_Category!$C$2:$C$26,MATCH($A26,Data_Category!$A$2:$A$26,0)) -> 782 | D26: =INDEX(Data_Category!$D$2:$D$26,MATCH($A26,Data_Category!$A$2:$A$26,0)) -> 783 | E26: =INDEX(Data_Category!$E$2:$E$26,MATCH($A26,Data_Category!$A$2:$A$26,0)) -> 48.932682 | F26: =INDEX(Data_Category!$F$2:$F$26,MATCH($A26,Data_Category!$A$2:$A$26,0)) -> 14.445517 | G26: =INDEX(Data_Category!$G$2:$G$26,MATCH($A26,Data_Category!$A$2:$A$26,0)) -> 3.7790549 | H26: =INDEX(Data_Category!$H$2:$H$26,MATCH($A26,Data_Category!$A$2:$A$26,0)) -> 0.2311622 | I26: =B26/SUM(Data_Category!$B$2:$B$26) -> 0.0027722722 | J26: =RANK(B26,Data_Category!$B$2:$B$26) -> 25
A28: Table is fully formula-driven: revenue rank via LARGE(), category name via INDEX/MATCH against Data_Category. No values are pasted.

Sheet State_Analysis
A1: customer_state | B1: revenue | C1: total_orders | D1: total_customers | E1: avg_delivery_days | F1: late_delivery_rate | G1: avg_review_score | H1: aov | I1: % of Total Revenue | J1: Rank
A2: =INDEX(Data_State!$A$2:$A$28,MATCH(B2,Data_State!$B$2:$B$28,0)) -> SP | B2: =LARGE(Data_State!$B$2:$B$28,1) -> 7350781.4 | C2: =INDEX(Data_State!$C$2:$C$28,MATCH($A2,Data_State!$A$2:$A$28,0)) -> 39925 | D2: =INDEX(Data_State!$D$2:$D$28,MATCH($A2,Data_State!$A$2:$A$28,0)) -> 39925 | E2: =INDEX(Data_State!$E$2:$E$28,MATCH($A2,Data_State!$A$2:$A$28,0)) -> 8.5672372 | F2: =INDEX(Data_State!$F$2:$F$28,MATCH($A2,Data_State!$A$2:$A$28,0)) -> 0.23432437 | G2: =INDEX(Data_State!$G$2:$G$28,MATCH($A2,Data_State!$A$2:$A$28,0)) -> 3.8441897 | H2: =INDEX(Data_State!$H$2:$H$28,MATCH($A2,Data_State!$A$2:$A$28,0)) -> 184.11475 | I2: =B2/SUM(Data_State!$B$2:$B$28) -> 0.41064612 | J2: =RANK(B2,Data_State!$B$2:$B$28) -> 1
A3: =INDEX(Data_State!$A$2:$A$28,MATCH(B3,Data_State!$B$2:$B$28,0)) -> RJ | B3: =LARGE(Data_State!$B$2:$B$28,2) -> 2301497.5 | C3: =INDEX(Data_State!$C$2:$C$28,MATCH($A3,Data_State!$A$2:$A$28,0)) -> 12360 | D3: =INDEX(Data_State!$D$2:$D$28,MATCH($A3,Data_State!$A$2:$A$28,0)) -> 12360 | E3: =INDEX(Data_State!$E$2:$E$28,MATCH($A3,Data_State!$A$2:$A$28,0)) -> 8.5175138 | F3: =INDEX(Data_State!$F$2:$F$28,MATCH($A3,Data_State!$A$2:$A$28,0)) -> 0.23771237 | G3: =INDEX(Data_State!$G$2:$G$28,MATCH($A3,Data_State!$A$2:$A$28,0)) -> 3.8457666 | H3: =INDEX(Data_State!$H$2:$H$28,MATCH($A3,Data_State!$A$2:$A$28,0)) -> 186.2053 | I3: =B3/SUM(Data_State!$B$2:$B$28) -> 0.1285715 | J3: =RANK(B3,Data_State!$B$2:$B$28) -> 2
A4: =INDEX(Data_State!$A$2:$A$28,MATCH(B4,Data_State!$B$2:$B$28,0)) -> MG | B4: =LARGE(Data_State!$B$2:$B$28,3) -> 1931899 | C4: =INDEX(Data_State!$C$2:$C$28,MATCH($A4,Data_State!$A$2:$A$28,0)) -> 10464 | D4: =INDEX(Data_State!$D$2:$D$28,MATCH($A4,Data_State!$A$2:$A$28,0)) -> 10464 | E4: =INDEX(Data_State!$E$2:$E$28,MATCH($A4,Data_State!$A$2:$A$28,0)) -> 8.5523174 | F4: =INDEX(Data_State!$F$2:$F$28,MATCH($A4,Data_State!$A$2:$A$28,0)) -> 0.23314399 | G4: =INDEX(Data_State!$G$2:$G$28,MATCH($A4,Data_State!$A$2:$A$28,0)) -> 3.8508274 | H4: =INDEX(Data_State!$H$2:$H$28,MATCH($A4,Data_State!$A$2:$A$28,0)) -> 184.62337 | I4: =B4/SUM(Data_State!$B$2:$B$28) -> 0.10792415 | J4: =RANK(B4,Data_State!$B$2:$B$28) -> 3
A5: =INDEX(Data_State!$A$2:$A$28,MATCH(B5,Data_State!$B$2:$B$28,0)) -> PR | B5: =LARGE(Data_State!$B$2:$B$28,4) -> 1040173.9 | C5: =INDEX(Data_State!$C$2:$C$28,MATCH($A5,Data_State!$A$2:$A$28,0)) -> 5717 | D5: =INDEX(Data_State!$D$2:$D$28,MATCH($A5,Data_State!$A$2:$A$28,0)) -> 5717 | E5: =INDEX(Data_State!$E$2:$E$28,MATCH($A5,Data_State!$A$2:$A$28,0)) -> 8.5653619 | F5: =INDEX(Data_State!$F$2:$F$28,MATCH($A5,Data_State!$A$2:$A$28,0)) -> 0.22744446 | G5: =INDEX(Data_State!$G$2:$G$28,MATCH($A5,Data_State!$A$2:$A$28,0)) -> 3.8455493 | H5: =INDEX(Data_State!$H$2:$H$28,MATCH($A5,Data_State!$A$2:$A$28,0)) -> 181.94401 | I5: =B5/SUM(Data_State!$B$2:$B$28) -> 0.058108567 | J5: =RANK(B5,Data_State!$B$2:$B$28) -> 4
A6: =INDEX(Data_State!$A$2:$A$28,MATCH(B6,Data_State!$B$2:$B$28,0)) -> RS | B6: =LARGE(Data_State!$B$2:$B$28,5) -> 1032167.1 | C6: =INDEX(Data_State!$C$2:$C$28,MATCH($A6,Data_State!$A$2:$A$28,0)) -> 5647 | D6: =INDEX(Data_State!$D$2:$D$28,MATCH($A6,Data_State!$A$2:$A$28,0)) -> 5647 | E6: =INDEX(Data_State!$E$2:$E$28,MATCH($A6,Data_State!$A$2:$A$28,0)) -> 8.6054212 | F6: =INDEX(Data_State!$F$2:$F$28,MATCH($A6,Data_State!$A$2:$A$28,0)) -> 0.22855383 | G6: =INDEX(Data_State!$G$2:$G$28,MATCH($A6,Data_State!$A$2:$A$28,0)) -> 3.8285846 | H6: =INDEX(Data_State!$H$2:$H$28,MATCH($A6,Data_State!$A$2:$A$28,0)) -> 182.78149 | I6: =B6/SUM(Data_State!$B$2:$B$28) -> 0.057661271 | J6: =RANK(B6,Data_State!$B$2:$B$28) -> 5
A7: =INDEX(Data_State!$A$2:$A$28,MATCH(B7,Data_State!$B$2:$B$28,0)) -> SC | B7: =LARGE(Data_State!$B$2:$B$28,6) -> 675687.66 | C7: =INDEX(Data_State!$C$2:$C$28,MATCH($A7,Data_State!$A$2:$A$28,0)) -> 3773 | D7: =INDEX(Data_State!$D$2:$D$28,MATCH($A7,Data_State!$A$2:$A$28,0)) -> 3773 | E7: =INDEX(Data_State!$E$2:$E$28,MATCH($A7,Data_State!$A$2:$A$28,0)) -> 8.6993267 | F7: =INDEX(Data_State!$F$2:$F$28,MATCH($A7,Data_State!$A$2:$A$28,0)) -> 0.23380543 | G7: =INDEX(Data_State!$G$2:$G$28,MATCH($A7,Data_State!$A$2:$A$28,0)) -> 3.8260971 | H7: =INDEX(Data_State!$H$2:$H$28,MATCH($A7,Data_State!$A$2:$A$28,0)) -> 179.08499 | I7: =B7/SUM(Data_State!$B$2:$B$28) -> 0.037746805 | J7: =RANK(B7,Data_State!$B$2:$B$28) -> 6
A8: =INDEX(Data_State!$A$2:$A$28,MATCH(B8,Data_State!$B$2:$B$28,0)) -> BA | B8: =LARGE(Data_State!$B$2:$B$28,7) -> 637932.59 | C8: =INDEX(Data_State!$C$2:$C$28,MATCH($A8,Data_State!$A$2:$A$28,0)) -> 3291 | D8: =INDEX(Data_State!$D$2:$D$28,MATCH($A8,Data_State!$A$2:$A$28,0)) -> 3291 | E8: =INDEX(Data_State!$E$2:$E$28,MATCH($A8,Data_State!$A$2:$A$28,0)) -> 11.675868 | F8: =INDEX(Data_State!$F$2:$F$28,MATCH($A8,Data_State!$A$2:$A$28,0)) -> 0.27392219 | G8: =INDEX(Data_State!$G$2:$G$28,MATCH($A8,Data_State!$A$2:$A$28,0)) -> 3.8041535 | H8: =INDEX(Data_State!$H$2:$H$28,MATCH($A8,Data_State!$A$2:$A$28,0)) -> 193.84156 | I8: =B8/SUM(Data_State!$B$2:$B$28) -> 0.035637646 | J8: =RANK(B8,Data_State!$B$2:$B$28) -> 7
A9: =INDEX(Data_State!$A$2:$A$28,MATCH(B9,Data_State!$B$2:$B$28,0)) -> DF | B9: =LARGE(Data_State!$B$2:$B$28,8) -> 442969.55 | C9: =INDEX(Data_State!$C$2:$C$28,MATCH($A9,Data_State!$A$2:$A$28,0)) -> 2354 | D9: =INDEX(Data_State!$D$2:$D$28,MATCH($A9,Data_State!$A$2:$A$28,0)) -> 2354 | E9: =INDEX(Data_State!$E$2:$E$28,MATCH($A9,Data_State!$A$2:$A$28,0)) -> 11.600818 | F9: =INDEX(Data_State!$F$2:$F$28,MATCH($A9,Data_State!$A$2:$A$28,0)) -> 0.28645833 | G9: =INDEX(Data_State!$G$2:$G$28,MATCH($A9,Data_State!$A$2:$A$28,0)) -> 3.7775298 | H9: =INDEX(Data_State!$H$2:$H$28,MATCH($A9,Data_State!$A$2:$A$28,0)) -> 188.17738 | I9: =B9/SUM(Data_State!$B$2:$B$28) -> 0.024746176 | J9: =RANK(B9,Data_State!$B$2:$B$28) -> 8
A10: =INDEX(Data_State!$A$2:$A$28,MATCH(B10,Data_State!$B$2:$B$28,0)) -> GO | B10: =LARGE(Data_State!$B$2:$B$28,9) -> 367749.68 | C10: =INDEX(Data_State!$C$2:$C$28,MATCH($A10,Data_State!$A$2:$A$28,0)) -> 1908 | D10: =INDEX(Data_State!$D$2:$D$28,MATCH($A10,Data_State!$A$2:$A$28,0)) -> 1908 | E10: =INDEX(Data_State!$E$2:$E$28,MATCH($A10,Data_State!$A$2:$A$28,0)) -> 11.438859 | F10: =INDEX(Data_State!$F$2:$F$28,MATCH($A10,Data_State!$A$2:$A$28,0)) -> 0.26811594 | G10: =INDEX(Data_State!$G$2:$G$28,MATCH($A10,Data_State!$A$2:$A$28,0)) -> 3.7971014 | H10: =INDEX(Data_State!$H$2:$H$28,MATCH($A10,Data_State!$A$2:$A$28,0)) -> 192.74092 | I10: =B10/SUM(Data_State!$B$2:$B$28) -> 0.020544072 | J10: =RANK(B10,Data_State!$B$2:$B$28) -> 9
A11: =INDEX(Data_State!$A$2:$A$28,MATCH(B11,Data_State!$B$2:$B$28,0)) -> PE | B11: =LARGE(Data_State!$B$2:$B$28,10) -> 329110.58 | C11: =INDEX(Data_State!$C$2:$C$28,MATCH($A11,Data_State!$A$2:$A$28,0)) -> 1713 | D11: =INDEX(Data_State!$D$2:$D$28,MATCH($A11,Data_State!$A$2:$A$28,0)) -> 1713 | E11: =INDEX(Data_State!$E$2:$E$28,MATCH($A11,Data_State!$A$2:$A$28,0)) -> 11.542494 | F11: =INDEX(Data_State!$F$2:$F$28,MATCH($A11,Data_State!$A$2:$A$28,0)) -> 0.25648855 | G11: =INDEX(Data_State!$G$2:$G$28,MATCH($A11,Data_State!$A$2:$A$28,0)) -> 3.8030534 | H11: =INDEX(Data_State!$H$2:$H$28,MATCH($A11,Data_State!$A$2:$A$28,0)) -> 192.12527 | I11: =B11/SUM(Data_State!$B$2:$B$28) -> 0.018385526 | J11: =RANK(B11,Data_State!$B$2:$B$28) -> 10
A12: =INDEX(Data_State!$A$2:$A$28,MATCH(B12,Data_State!$B$2:$B$28,0)) -> CE | B12: =LARGE(Data_State!$B$2:$B$28,11) -> 269511.08 | C12: =INDEX(Data_State!$C$2:$C$28,MATCH($A12,Data_State!$A$2:$A$28,0)) -> 1425 | D12: =INDEX(Data_State!$D$2:$D$28,MATCH($A12,Data_State!$A$2:$A$28,0)) -> 1425 | E12: =INDEX(Data_State!$E$2:$E$28,MATCH($A12,Data_State!$A$2:$A$28,0)) -> 11.477995 | F12: =INDEX(Data_State!$F$2:$F$28,MATCH($A12,Data_State!$A$2:$A$28,0)) -> 0.26772616 | G12: =INDEX(Data_State!$G$2:$G$28,MATCH($A12,Data_State!$A$2:$A$28,0)) -> 3.8215159 | H12: =INDEX(Data_State!$H$2:$H$28,MATCH($A12,Data_State!$A$2:$A$28,0)) -> 189.13058 | I12: =B12/SUM(Data_State!$B$2:$B$28) -> 0.015056043 | J12: =RANK(B12,Data_State!$B$2:$B$28) -> 11
A13: =INDEX(Data_State!$A$2:$A$28,MATCH(B13,Data_State!$B$2:$B$28,0)) -> ES | B13: =LARGE(Data_State!$B$2:$B$28,12) -> 216827.84 | C13: =INDEX(Data_State!$C$2:$C$28,MATCH($A13,Data_State!$A$2:$A$28,0)) -> 1159 | D13: =INDEX(Data_State!$D$2:$D$28,MATCH($A13,Data_State!$A$2:$A$28,0)) -> 1159 | E13: =INDEX(Data_State!$E$2:$E$28,MATCH($A13,Data_State!$A$2:$A$28,0)) -> 11.617053 | F13: =INDEX(Data_State!$F$2:$F$28,MATCH($A13,Data_State!$A$2:$A$28,0)) -> 0.29020194 | G13: =INDEX(Data_State!$G$2:$G$28,MATCH($A13,Data_State!$A$2:$A$28,0)) -> 3.7412117 | H13: =INDEX(Data_State!$H$2:$H$28,MATCH($A13,Data_State!$A$2:$A$28,0)) -> 187.08183 | I13: =B13/SUM(Data_State!$B$2:$B$28) -> 0.012112931 | J13: =RANK(B13,Data_State!$B$2:$B$28) -> 12
A14: =INDEX(Data_State!$A$2:$A$28,MATCH(B14,Data_State!$B$2:$B$28,0)) -> PA | B14: =LARGE(Data_State!$B$2:$B$28,13) -> 215025.41 | C14: =INDEX(Data_State!$C$2:$C$28,MATCH($A14,Data_State!$A$2:$A$28,0)) -> 1134 | D14: =INDEX(Data_State!$D$2:$D$28,MATCH($A14,Data_State!$A$2:$A$28,0)) -> 1134 | E14: =INDEX(Data_State!$E$2:$E$28,MATCH($A14,Data_State!$A$2:$A$28,0)) -> 11.647692 | F14: =INDEX(Data_State!$F$2:$F$28,MATCH($A14,Data_State!$A$2:$A$28,0)) -> 0.27538462 | G14: =INDEX(Data_State!$G$2:$G$28,MATCH($A14,Data_State!$A$2:$A$28,0)) -> 3.7515385 | H14: =INDEX(Data_State!$H$2:$H$28,MATCH($A14,Data_State!$A$2:$A$28,0)) -> 189.61676 | I14: =B14/SUM(Data_State!$B$2:$B$28) -> 0.01201224 | J14: =RANK(B14,Data_State!$B$2:$B$28) -> 13
A15: =INDEX(Data_State!$A$2:$A$28,MATCH(B15,Data_State!$B$2:$B$28,0)) -> MT | B15: =LARGE(Data_State!$B$2:$B$28,14) -> 162995.59 | C15: =INDEX(Data_State!$C$2:$C$28,MATCH($A15,Data_State!$A$2:$A$28,0)) -> 852 | D15: =INDEX(Data_State!$D$2:$D$28,MATCH($A15,Data_State!$A$2:$A$28,0)) -> 852 | E15: =INDEX(Data_State!$E$2:$E$28,MATCH($A15,Data_State!$A$2:$A$28,0)) -> 11.52444 | F15: =INDEX(Data_State!$F$2:$F$28,MATCH($A15,Data_State!$A$2:$A$28,0)) -> 0.25152749 | G15: =INDEX(Data_State!$G$2:$G$28,MATCH($A15,Data_State!$A$2:$A$28,0)) -> 3.8655804 | H15: =INDEX(Data_State!$H$2:$H$28,MATCH($A15,Data_State!$A$2:$A$28,0)) -> 191.30938 | I15: =B15/SUM(Data_State!$B$2:$B$28) -> 0.0091056315 | J15: =RANK(B15,Data_State!$B$2:$B$28) -> 14
A16: =INDEX(Data_State!$A$2:$A$28,MATCH(B16,Data_State!$B$2:$B$28,0)) -> MA | B16: =LARGE(Data_State!$B$2:$B$28,15) -> 140136.83 | C16: =INDEX(Data_State!$C$2:$C$28,MATCH($A16,Data_State!$A$2:$A$28,0)) -> 740 | D16: =INDEX(Data_State!$D$2:$D$28,MATCH($A16,Data_State!$A$2:$A$28,0)) -> 740 | E16: =INDEX(Data_State!$E$2:$E$28,MATCH($A16,Data_State!$A$2:$A$28,0)) -> 11.270784 | F16: =INDEX(Data_State!$F$2:$F$28,MATCH($A16,Data_State!$A$2:$A$28,0)) -> 0.31828979 | G16: =INDEX(Data_State!$G$2:$G$28,MATCH($A16,Data_State!$A$2:$A$28,0)) -> 3.6686461 | H16: =INDEX(Data_State!$H$2:$H$28,MATCH($A16,Data_State!$A$2:$A$28,0)) -> 189.37409 | I16: =B16/SUM(Data_State!$B$2:$B$28) -> 0.0078286433 | J16: =RANK(B16,Data_State!$B$2:$B$28) -> 15
A17: =INDEX(Data_State!$A$2:$A$28,MATCH(B17,Data_State!$B$2:$B$28,0)) -> MS | B17: =LARGE(Data_State!$B$2:$B$28,16) -> 128830.96 | C17: =INDEX(Data_State!$C$2:$C$28,MATCH($A17,Data_State!$A$2:$A$28,0)) -> 666 | D17: =INDEX(Data_State!$D$2:$D$28,MATCH($A17,Data_State!$A$2:$A$28,0)) -> 666 | E17: =INDEX(Data_State!$E$2:$E$28,MATCH($A17,Data_State!$A$2:$A$28,0)) -> 11.387306 | F17: =INDEX(Data_State!$F$2:$F$28,MATCH($A17,Data_State!$A$2:$A$28,0)) -> 0.30181347 | G17: =INDEX(Data_State!$G$2:$G$28,MATCH($A17,Data_State!$A$2:$A$28,0)) -> 3.7642487 | H17: =INDEX(Data_State!$H$2:$H$28,MATCH($A17,Data_State!$A$2:$A$28,0)) -> 193.43988 | I17: =B17/SUM(Data_State!$B$2:$B$28) -> 0.007197049 | J17: =RANK(B17,Data_State!$B$2:$B$28) -> 16
A18: =INDEX(Data_State!$A$2:$A$28,MATCH(B18,Data_State!$B$2:$B$28,0)) -> RN | B18: =LARGE(Data_State!$B$2:$B$28,17) -> 113124.3 | C18: =INDEX(Data_State!$C$2:$C$28,MATCH($A18,Data_State!$A$2:$A$28,0)) -> 594 | D18: =INDEX(Data_State!$D$2:$D$28,MATCH($A18,Data_State!$A$2:$A$28,0)) -> 594 | E18: =INDEX(Data_State!$E$2:$E$28,MATCH($A18,Data_State!$A$2:$A$28,0)) -> 11.645441 | F18: =INDEX(Data_State!$F$2:$F$28,MATCH($A18,Data_State!$A$2:$A$28,0)) -> 0.3154848 | G18: =INDEX(Data_State!$G$2:$G$28,MATCH($A18,Data_State!$A$2:$A$28,0)) -> 3.7756874 | H18: =INDEX(Data_State!$H$2:$H$28,MATCH($A18,Data_State!$A$2:$A$28,0)) -> 190.44495 | I18: =B18/SUM(Data_State!$B$2:$B$28) -> 0.0063196077 | J18: =RANK(B18,Data_State!$B$2:$B$28) -> 17
A19: =INDEX(Data_State!$A$2:$A$28,MATCH(B19,Data_State!$B$2:$B$28,0)) -> PB | B19: =LARGE(Data_State!$B$2:$B$28,18) -> 100852.32 | C19: =INDEX(Data_State!$C$2:$C$28,MATCH($A19,Data_State!$A$2:$A$28,0)) -> 529 | D19: =INDEX(Data_State!$D$2:$D$28,MATCH($A19,Data_State!$A$2:$A$28,0)) -> 529 | E19: =INDEX(Data_State!$E$2:$E$28,MATCH($A19,Data_State!$A$2:$A$28,0)) -> 11.543919 | F19: =INDEX(Data_State!$F$2:$F$28,MATCH($A19,Data_State!$A$2:$A$28,0)) -> 0.28885135 | G19: =INDEX(Data_State!$G$2:$G$28,MATCH($A19,Data_State!$A$2:$A$28,0)) -> 3.8175676 | H19: =INDEX(Data_State!$H$2:$H$28,MATCH($A19,Data_State!$A$2:$A$28,0)) -> 190.64711 | I19: =B19/SUM(Data_State!$B$2:$B$28) -> 0.0056340424 | J19: =RANK(B19,Data_State!$B$2:$B$28) -> 18
A20: =INDEX(Data_State!$A$2:$A$28,MATCH(B20,Data_State!$B$2:$B$28,0)) -> PI | B20: =LARGE(Data_State!$B$2:$B$28,19) -> 95364.47 | C20: =INDEX(Data_State!$C$2:$C$28,MATCH($A20,Data_State!$A$2:$A$28,0)) -> 496 | D20: =INDEX(Data_State!$D$2:$D$28,MATCH($A20,Data_State!$A$2:$A$28,0)) -> 496 | E20: =INDEX(Data_State!$E$2:$E$28,MATCH($A20,Data_State!$A$2:$A$28,0)) -> 11.54321 | F20: =INDEX(Data_State!$F$2:$F$28,MATCH($A20,Data_State!$A$2:$A$28,0)) -> 0.28042328 | G20: =INDEX(Data_State!$G$2:$G$28,MATCH($A20,Data_State!$A$2:$A$28,0)) -> 3.8818342 | H20: =INDEX(Data_State!$H$2:$H$28,MATCH($A20,Data_State!$A$2:$A$28,0)) -> 192.26708 | I20: =B20/SUM(Data_State!$B$2:$B$28) -> 0.0053274676 | J20: =RANK(B20,Data_State!$B$2:$B$28) -> 19
A21: =INDEX(Data_State!$A$2:$A$28,MATCH(B21,Data_State!$B$2:$B$28,0)) -> AL | B21: =LARGE(Data_State!$B$2:$B$28,20) -> 85414.21 | C21: =INDEX(Data_State!$C$2:$C$28,MATCH($A21,Data_State!$A$2:$A$28,0)) -> 445 | D21: =INDEX(Data_State!$D$2:$D$28,MATCH($A21,Data_State!$A$2:$A$28,0)) -> 445 | E21: =INDEX(Data_State!$E$2:$E$28,MATCH($A21,Data_State!$A$2:$A$28,0)) -> 12.153992 | F21: =INDEX(Data_State!$F$2:$F$28,MATCH($A21,Data_State!$A$2:$A$28,0)) -> 0.24904943 | G21: =INDEX(Data_State!$G$2:$G$28,MATCH($A21,Data_State!$A$2:$A$28,0)) -> 3.7414449 | H21: =INDEX(Data_State!$H$2:$H$28,MATCH($A21,Data_State!$A$2:$A$28,0)) -> 191.94204 | I21: =B21/SUM(Data_State!$B$2:$B$28) -> 0.0047716034 | J21: =RANK(B21,Data_State!$B$2:$B$28) -> 20
A22: =INDEX(Data_State!$A$2:$A$28,MATCH(B22,Data_State!$B$2:$B$28,0)) -> SE | B22: =LARGE(Data_State!$B$2:$B$28,21) -> 79841.85 | C22: =INDEX(Data_State!$C$2:$C$28,MATCH($A22,Data_State!$A$2:$A$28,0)) -> 414 | D22: =INDEX(Data_State!$D$2:$D$28,MATCH($A22,Data_State!$A$2:$A$28,0)) -> 414 | E22: =INDEX(Data_State!$E$2:$E$28,MATCH($A22,Data_State!$A$2:$A$28,0)) -> 12.211934 | F22: =INDEX(Data_State!$F$2:$F$28,MATCH($A22,Data_State!$A$2:$A$28,0)) -> 0.30864198 | G22: =INDEX(Data_State!$G$2:$G$28,MATCH($A22,Data_State!$A$2:$A$28,0)) -> 3.7263374 | H22: =INDEX(Data_State!$H$2:$H$28,MATCH($A22,Data_State!$A$2:$A$28,0)) -> 192.85471 | I22: =B22/SUM(Data_State!$B$2:$B$28) -> 0.0044603076 | J22: =RANK(B22,Data_State!$B$2:$B$28) -> 21
A23: =INDEX(Data_State!$A$2:$A$28,MATCH(B23,Data_State!$B$2:$B$28,0)) -> RO | B23: =LARGE(Data_State!$B$2:$B$28,22) -> 51963.2 | C23: =INDEX(Data_State!$C$2:$C$28,MATCH($A23,Data_State!$A$2:$A$28,0)) -> 275 | D23: =INDEX(Data_State!$D$2:$D$28,MATCH($A23,Data_State!$A$2:$A$28,0)) -> 275 | E23: =INDEX(Data_State!$E$2:$E$28,MATCH($A23,Data_State!$A$2:$A$28,0)) -> 11.286164 | F23: =INDEX(Data_State!$F$2:$F$28,MATCH($A23,Data_State!$A$2:$A$28,0)) -> 0.29559748 | G23: =INDEX(Data_State!$G$2:$G$28,MATCH($A23,Data_State!$A$2:$A$28,0)) -> 3.8427673 | H23: =INDEX(Data_State!$H$2:$H$28,MATCH($A23,Data_State!$A$2:$A$28,0)) -> 188.95709 | I23: =B23/SUM(Data_State!$B$2:$B$28) -> 0.0029028868 | J23: =RANK(B23,Data_State!$B$2:$B$28) -> 22
A24: =INDEX(Data_State!$A$2:$A$28,MATCH(B24,Data_State!$B$2:$B$28,0)) -> TO | B24: =LARGE(Data_State!$B$2:$B$28,23) -> 51378.34 | C24: =INDEX(Data_State!$C$2:$C$28,MATCH($A24,Data_State!$A$2:$A$28,0)) -> 267 | D24: =INDEX(Data_State!$D$2:$D$28,MATCH($A24,Data_State!$A$2:$A$28,0)) -> 267 | E24: =INDEX(Data_State!$E$2:$E$28,MATCH($A24,Data_State!$A$2:$A$28,0)) -> 11.425325 | F24: =INDEX(Data_State!$F$2:$F$28,MATCH($A24,Data_State!$A$2:$A$28,0)) -> 0.24675325 | G24: =INDEX(Data_State!$G$2:$G$28,MATCH($A24,Data_State!$A$2:$A$28,0)) -> 3.9253247 | H24: =INDEX(Data_State!$H$2:$H$28,MATCH($A24,Data_State!$A$2:$A$28,0)) -> 192.42824 | I24: =B24/SUM(Data_State!$B$2:$B$28) -> 0.002870214 | J24: =RANK(B24,Data_State!$B$2:$B$28) -> 23
A25: =INDEX(Data_State!$A$2:$A$28,MATCH(B25,Data_State!$B$2:$B$28,0)) -> AM | B25: =LARGE(Data_State!$B$2:$B$28,24) -> 32900.88 | C25: =INDEX(Data_State!$C$2:$C$28,MATCH($A25,Data_State!$A$2:$A$28,0)) -> 169 | D25: =INDEX(Data_State!$D$2:$D$28,MATCH($A25,Data_State!$A$2:$A$28,0)) -> 169 | E25: =INDEX(Data_State!$E$2:$E$28,MATCH($A25,Data_State!$A$2:$A$28,0)) -> 11.735751 | F25: =INDEX(Data_State!$F$2:$F$28,MATCH($A25,Data_State!$A$2:$A$28,0)) -> 0.26943005 | G25: =INDEX(Data_State!$G$2:$G$28,MATCH($A25,Data_State!$A$2:$A$28,0)) -> 3.8082902 | H25: =INDEX(Data_State!$H$2:$H$28,MATCH($A25,Data_State!$A$2:$A$28,0)) -> 194.67976 | I25: =B25/SUM(Data_State!$B$2:$B$28) -> 0.001837984 | J25: =RANK(B25,Data_State!$B$2:$B$28) -> 24
A26: =INDEX(Data_State!$A$2:$A$28,MATCH(B26,Data_State!$B$2:$B$28,0)) -> AC | B26: =LARGE(Data_State!$B$2:$B$28,25) -> 18923.76 | C26: =INDEX(Data_State!$C$2:$C$28,MATCH($A26,Data_State!$A$2:$A$28,0)) -> 92 | D26: =INDEX(Data_State!$D$2:$D$28,MATCH($A26,Data_State!$A$2:$A$28,0)) -> 92 | E26: =INDEX(Data_State!$E$2:$E$28,MATCH($A26,Data_State!$A$2:$A$28,0)) -> 12.252427 | F26: =INDEX(Data_State!$F$2:$F$28,MATCH($A26,Data_State!$A$2:$A$28,0)) -> 0.23300971 | G26: =INDEX(Data_State!$G$2:$G$28,MATCH($A26,Data_State!$A$2:$A$28,0)) -> 3.5825243 | H26: =INDEX(Data_State!$H$2:$H$28,MATCH($A26,Data_State!$A$2:$A$28,0)) -> 205.69304 | I26: =B26/SUM(Data_State!$B$2:$B$28) -> 0.0010571623 | J26: =RANK(B26,Data_State!$B$2:$B$28) -> 25
A27: =INDEX(Data_State!$A$2:$A$28,MATCH(B27,Data_State!$B$2:$B$28,0)) -> AP | B27: =LARGE(Data_State!$B$2:$B$28,26) -> 16449.27 | C27: =INDEX(Data_State!$C$2:$C$28,MATCH($A27,Data_State!$A$2:$A$28,0)) -> 90 | D27: =INDEX(Data_State!$D$2:$D$28,MATCH($A27,Data_State!$A$2:$A$28,0)) -> 90 | E27: =INDEX(Data_State!$E$2:$E$28,MATCH($A27,Data_State!$A$2:$A$28,0)) -> 11.717172 | F27: =INDEX(Data_State!$F$2:$F$28,MATCH($A27,Data_State!$A$2:$A$28,0)) -> 0.26262626 | G27: =INDEX(Data_State!$G$2:$G$28,MATCH($A27,Data_State!$A$2:$A$28,0)) -> 3.4646465 | H27: =INDEX(Data_State!$H$2:$H$28,MATCH($A27,Data_State!$A$2:$A$28,0)) -> 182.76967 | I27: =B27/SUM(Data_State!$B$2:$B$28) -> 0.00091892665 | J27: =RANK(B27,Data_State!$B$2:$B$28) -> 26
A28: =INDEX(Data_State!$A$2:$A$28,MATCH(B28,Data_State!$B$2:$B$28,0)) -> RR | B28: =LARGE(Data_State!$B$2:$B$28,27) -> 11016.49 | C28: =INDEX(Data_State!$C$2:$C$28,MATCH($A28,Data_State!$A$2:$A$28,0)) -> 52 | D28: =INDEX(Data_State!$D$2:$D$28,MATCH($A28,Data_State!$A$2:$A$28,0)) -> 52 | E28: =INDEX(Data_State!$E$2:$E$28,MATCH($A28,Data_State!$A$2:$A$28,0)) -> 11.278689 | F28: =INDEX(Data_State!$F$2:$F$28,MATCH($A28,Data_State!$A$2:$A$28,0)) -> 0.2295082 | G28: =INDEX(Data_State!$G$2:$G$28,MATCH($A28,Data_State!$A$2:$A$28,0)) -> 3.8032787 | H28: =INDEX(Data_State!$H$2:$H$28,MATCH($A28,Data_State!$A$2:$A$28,0)) -> 211.85558 | I28: =B28/SUM(Data_State!$B$2:$B$28) -> 0.0006154283 | J28: =RANK(B28,Data_State!$B$2:$B$28) -> 27
A30: Table is fully formula-driven: revenue rank via LARGE(), state name via INDEX/MATCH against Data_State.

Sheet Delivery_Review
A1: review_score | B1: total_orders | C1: avg_delivery_days | D1: avg_delay_days | E1: late_delivery_rate | F1: % of Reviews
A2: =Data_ReviewDelivery!A2 -> 1 | B2: =Data_ReviewDelivery!B2 -> 8589 | C2: =Data_ReviewDelivery!C2 -> 9.5242752 | D2: =Data_ReviewDelivery!D2 -> -1.2200489 | E2: =Data_ReviewDelivery!E2 -> 0.47782047 | F2: =B2/SUM(Data_ReviewDelivery!$B$2:$B$6) -> 0.088958167
A3: =Data_ReviewDelivery!A3 -> 2 | B3: =Data_ReviewDelivery!B3 -> 7962 | C3: =Data_ReviewDelivery!C3 -> 9.7410198 | D3: =Data_ReviewDelivery!D3 -> -0.7793268 | E3: =Data_ReviewDelivery!E3 -> 0.54220045 | F3: =B3/SUM(Data_ReviewDelivery!$B$2:$B$6) -> 0.08246419
A4: =Data_ReviewDelivery!A4 -> 3 | B4: =Data_ReviewDelivery!B4 -> 15686 | C4: =Data_ReviewDelivery!C4 -> 9.5414382 | D4: =Data_ReviewDelivery!D4 -> -0.83507586 | E4: =Data_ReviewDelivery!E4 -> 0.53327808 | F4: =B4/SUM(Data_ReviewDelivery!$B$2:$B$6) -> 0.16246336
A5: =Data_ReviewDelivery!A5 -> 4 | B5: =Data_ReviewDelivery!B5 -> 23047 | C5: =Data_ReviewDelivery!C5 -> 9.3263331 | D5: =Data_ReviewDelivery!D5 -> -2.4296438 | E5: =Data_ReviewDelivery!E5 -> 0.28446219 | F5: =B5/SUM(Data_ReviewDelivery!$B$2:$B$6) -> 0.23870286
A6: =Data_ReviewDelivery!A6 -> 5 | B6: =Data_ReviewDelivery!B6 -> 41267 | C6: =Data_ReviewDelivery!C6 -> 8.7087261 | D6: =Data_ReviewDelivery!D6 -> -4.282211 | E6: =Data_ReviewDelivery!E6 -> 0 | F6: =B6/SUM(Data_ReviewDelivery!$B$2:$B$6) -> 0.42741142
A8: Pulled live from Data_ReviewDelivery; % of Reviews calculated with formula.

Sheet Payment_Summary
A1: payment_type | B1: total_orders | C1: payment_value | D1: avg_payment | E1: % of Total Orders | F1: % of Total Revenue
A2: =Data_Payment!A2 -> credit_card | B2: =Data_Payment!B2 -> 71384 | C2: =Data_Payment!C2 -> 13222321 | D2: =C2/B2 -> 185.22807 | E2: =B2/SUM(Data_Payment!$B$2:$B$5) -> 0.73933983 | F2: =C2/SUM(Data_Payment!$C$2:$C$5) -> 0.73865543
A3: =Data_Payment!A3 -> boleto | B3: =Data_Payment!B3 -> 18438 | C3: =Data_Payment!C3 -> 3418278.4 | D3: =C3/B3 -> 185.39313 | E3: =B3/SUM(Data_Payment!$B$2:$B$5) -> 0.19096643 | F3: =C3/SUM(Data_Payment!$C$2:$C$5) -> 0.19095967
A4: =Data_Payment!A4 -> voucher | B4: =Data_Payment!B4 -> 4352 | C4: =Data_Payment!C4 -> 817509.64 | D4: =C4/B4 -> 187.84688 | E4: =B4/SUM(Data_Payment!$B$2:$B$5) -> 0.045074624 | F4: =C4/SUM(Data_Payment!$C$2:$C$5) -> 0.045669588
A5: =Data_Payment!A5 -> debit_card | B5: =Data_Payment!B5 -> 2377 | C5: =Data_Payment!C5 -> 442417.02 | D5: =C5/B5 -> 186.12411 | E5: =B5/SUM(Data_Payment!$B$2:$B$5) -> 0.024619113 | F5: =C5/SUM(Data_Payment!$C$2:$C$5) -> 0.024715309
A7: Pulled live from Data_Payment; avg_payment and % shares are calculated with formulas.

Sheet Source_Notes
A1: Item | B1: Details
A2: Dataset used in this workbook | B2: Synthetic Olist-style marketplace data generated for this portfolio package because direct dataset download was unavailable in the execution environment.
A3: Recommended real dataset | B3: Brazilian E-Commerce Public Dataset by Olist
A4: Kaggle URL | B4: https://www.kaggle.com/datasets/olistbr/brazilian-ecommerce
A5: GitHub mirror inspected | B5: https://github.com/spdrio/Brazilian-E-Commerce-Public-Dataset-by-Olist

Sheet Data_Category
A1: product_category_name_english | B1: revenue | C1: total_orders | D1: total_items | E1: avg_price | F1: avg_freight | G1: avg_review_score | H1: late_delivery_rate
A2: computers_accessories | B2: 1685925.4 | C2: 7507 | D2: 7589 | E2: 200.76994 | F2: 21.383892 | G2: 3.8348926 | H2: 0.24232442
A3: watches_gifts | B3: 1508123.3 | C3: 5907 | D3: 5957 | E3: 230.46382 | F3: 22.704428 | G3: 3.8341447 | H3: 0.24223602
A4: health_beauty | B4: 1432652.7 | C4: 9399 | D4: 9536 | E4: 131.9781 | F4: 18.258132 | G4: 3.8464765 | H4: 0.2457005
A5: furniture_decor | B5: 1424562.9 | C5: 7570 | D5: 7672 | E5: 165.93068 | F5: 19.752694 | G5: 3.830683 | H5: 0.24973931
A6: sports_leisure | B6: 1273178.4 | C6: 8590 | D6: 8710 | E6: 127.97638 | F6: 18.197953 | G6: 3.8061998 | H6: 0.24948335
A7: bed_bath_table | B7: 1214319.1 | C7: 10297 | D7: 10440 | E7: 99.512131 | F7: 16.801962 | G7: 3.8427203 | H7: 0.24272031
A8: electronics | B8: 928428.79 | C8: 3510 | D8: 3528 | E8: 240.02299 | F8: 23.137098 | G8: 3.86678 | H8: 0.23922902
A9: garden_tools | B9: 865718.48 | C9: 5291 | D9: 5328 | E9: 143.78362 | F9: 18.701077 | G9: 3.8209459 | H9: 0.2454955
A10: auto | B10: 858355.87 | C10: 4647 | D10: 4681 | E10: 163.61384 | F10: 19.756351 | G10: 3.8397778 | H10: 0.23435163
A11: cool_stuff | B11: 810594.84 | C11: 4086 | D11: 4109 | E11: 177.0273 | F11: 20.245722 | G11: 3.8352397 | H11: 0.2411779
A12: housewares | B12: 717020.21 | C12: 7160 | D12: 7230 | E12: 83.114823 | F12: 16.058097 | G12: 3.8127248 | H12: 0.23941909
A13: office_furniture | B13: 707103.23 | C13: 2311 | D13: 2323 | E13: 279.42672 | F13: 24.965549 | G13: 3.8286698 | H13: 0.23590185
... A26: food | B26: 49625.13 | C26: 782 | D26: 783 | E26: 48.932682 | F26: 14.445517 | G26: 3.7790549 | H26: 0.2311622
A28: Source: Python ETL output (data/cleaned/*.csv), generated by run_analysis.py from raw Olist-style transactional data.

Sheet Data_State
A1: customer_state | B1: revenue | C1: total_orders | D1: total_customers | E1: avg_delivery_days | F1: late_delivery_rate | G1: avg_review_score | H1: aov
A2: SP | B2: 7350781.4 | C2: 39925 | D2: 39925 | E2: 8.5672372 | F2: 0.23432437 | G2: 3.8441897 | H2: 184.11475
A3: RJ | B3: 2301497.5 | C3: 12360 | D3: 12360 | E3: 8.5175138 | F3: 0.23771237 | G3: 3.8457666 | H3: 186.2053
A4: MG | B4: 1931899 | C4: 10464 | D4: 10464 | E4: 8.5523174 | F4: 0.23314399 | G4: 3.8508274 | H4: 184.62337
A5: PR | B5: 1040173.9 | C5: 5717 | D5: 5717 | E5: 8.5653619 | F5: 0.22744446 | G5: 3.8455493 | H5: 181.94401
A6: RS | B6: 1032167.1 | C6: 5647 | D6: 5647 | E6: 8.6054212 | F6: 0.22855383 | G6: 3.8285846 | H6: 182.78149
A7: SC | B7: 675687.66 | C7: 3773 | D7: 3773 | E7: 8.6993267 | F7: 0.23380543 | G7: 3.8260971 | H7: 179.08499
A8: BA | B8: 637932.59 | C8: 3291 | D8: 3291 | E8: 11.675868 | F8: 0.27392219 | G8: 3.8041535 | H8: 193.84156
A9: DF | B9: 442969.55 | C9: 2354 | D9: 2354 | E9: 11.600818 | F9: 0.28645833 | G9: 3.7775298 | H9: 188.17738
A10: GO | B10: 367749.68 | C10: 1908 | D10: 1908 | E10: 11.438859 | F10: 0.26811594 | G10: 3.7971014 | H10: 192.74092
A11: PE | B11: 329110.58 | C11: 1713 | D11: 1713 | E11: 11.542494 | F11: 0.25648855 | G11: 3.8030534 | H11: 192.12527
A12: CE | B12: 269511.08 | C12: 1425 | D12: 1425 | E12: 11.477995 | F12: 0.26772616 | G12: 3.8215159 | H12: 189.13058
A13: ES | B13: 216827.84 | C13: 1159 | D13: 1159 | E13: 11.617053 | F13: 0.29020194 | G13: 3.7412117 | H13: 187.08183
... A28: RR | B28: 11016.49 | C28: 52 | D28: 52 | E28: 11.278689 | F28: 0.2295082 | G28: 3.8032787 | H28: 211.85558
A30: Source: Python ETL output (data/cleaned/*.csv), generated by run_analysis.py from raw Olist-style transactional data.

Sheet Data_Monthly
A1: order_month | B1: revenue | C1: total_orders | D1: total_customers | E1: avg_review_score | F1: late_delivery_rate | G1: aov
A2: 2016-09 | B2: 24367.4 | C2: 120 | D2: 120 | E2: 3.5070423 | F2: 0.28873239 | G2: 203.06167
A3: 2016-10 | B3: 79530.25 | C3: 430 | D3: 430 | E3: 3.7534791 | F3: 0.26441352 | G3: 184.95407
A4: 2016-11 | B4: 143085.49 | C4: 755 | D4: 755 | E4: 3.8957617 | F4: 0.22565865 | G4: 189.51721
A5: 2016-12 | B5: 216396.36 | C5: 1160 | D5: 1160 | E5: 3.85693 | F5: 0.2414307 | G5: 186.54859
A6: 2017-01 | B6: 289073.93 | C6: 1591 | D6: 1591 | E6: 3.8638111 | F6: 0.24437122 | G6: 181.69323
A7: 2017-02 | B7: 339718.38 | C7: 1851 | D7: 1851 | E7: 3.822054 | F7: 0.24372929 | G7: 183.53235
A8: 2017-03 | B8: 438741.8 | C8: 2435 | D8: 2435 | E8: 3.8461263 | F8: 0.23637016 | G8: 180.18144
A9: 2017-04 | B9: 509440.18 | C9: 2744 | D9: 2744 | E9: 3.8177511 | F9: 0.25300063 | G9: 185.65604
A10: 2017-05 | B10: 582457 | C10: 3129 | D10: 3129 | E10: 3.8468493 | F10: 0.2369863 | G10: 186.14797
A11: 2017-06 | B11: 636554.15 | C11: 3457 | D11: 3457 | E11: 3.8385155 | F11: 0.24147442 | G11: 184.13484
A12: 2017-07 | B12: 746312.1 | C12: 3960 | D12: 3960 | E12: 3.8176663 | F12: 0.23642312 | G12: 188.46265
A13: 2017-08 | B13: 786994.01 | C13: 4302 | D13: 4302 | E13: 3.8611336 | F13: 0.23805668 | G13: 182.93678
... A25: 2018-08 | B25: 962267.57 | C25: 5095 | D25: 5095 | E25: 3.8342336 | F25: 0.24155976 | G25: 188.86508
A27: Source: Python ETL output (data/cleaned/*.csv), generated by run_analysis.py from raw Olist-style transactional data.

Sheet Data_Payment
A1: payment_type | B1: total_orders | C1: payment_value | D1: avg_payment
A2: credit_card | B2: 71384 | C2: 13222321 | D2: 185.22807
A3: boleto | B3: 18438 | C3: 3418278.4 | D3: 185.39313
A4: voucher | B4: 4352 | C4: 817509.64 | D4: 187.84688
A5: debit_card | B5: 2377 | C5: 442417.02 | D5: 186.12411
A7: Source: Python ETL output (data/cleaned/*.csv), generated by run_analysis.py from raw Olist-style transactional data.

Sheet Data_ReviewDelivery
A1: review_score | B1: total_orders | C1: avg_delivery_days | D1: avg_delay_days | E1: late_delivery_rate
A2: 1 | B2: 8589 | C2: 9.5242752 | D2: -1.2200489 | E2: 0.47782047
A3: 2 | B3: 7962 | C3: 9.7410198 | D3: -0.7793268 | E3: 0.54220045
A4: 3 | B4: 15686 | C4: 9.5414382 | D4: -0.83507586 | E4: 0.53327808
A5: 4 | B5: 23047 | C5: 9.3263331 | D5: -2.4296438 | E5: 0.28446219
A6: 5 | B6: 41267 | C6: 8.7087261 | D6: -4.282211 | E6: 0
A8: Source: Python ETL output (data/cleaned/*.csv), generated by run_analysis.py from raw Olist-style transactional data.

Sheet Data_Sellers
A1: seller_rank | B1: seller_id | C1: revenue | D1: total_orders | E1: avg_review_score | F1: late_delivery_rate | G1: avg_delivery_days
A2: 1 | B2: a2ace083ea81f073ff464af92707ad18 | C2: 10890.74 | D2: 50 | E2: 3.82 | F2: 0.26 | G2: 8.98
A3: 2 | B3: 9b408b290e7f437646d16d4859a06615 | C3: 10371.58 | D3: 57 | E3: 4.0701754 | F3: 0.15789474 | G3: 9.122807
A4: 3 | B4: 5c7ecd2024c7a9f2af88e3a12cd17e00 | C4: 10343.96 | D4: 60 | E4: 3.7166667 | F4: 0.31666667 | G4: 9.65
A5: 4 | B5: cab3cb7599eba8553e5d4a3c0bed5fcf | C5: 10114.89 | D5: 53 | E5: 3.6981132 | F5: 0.32075472 | G5: 10.320755
A6: 5 | B6: 6f386a57fc43342bbae757552e8050b4 | C6: 10076.67 | D6: 45 | E6: 3.6222222 | F6: 0.31111111 | G6: 9.7777778
A7: 6 | B7: ddeff2d0c907c3d78fb2c5e30f00bfcd | C7: 10002.06 | D7: 61 | E7: 3.9180328 | F7: 0.24590164 | G7: 8.6557377
A8: 7 | B8: 994845c1f54e0d515f90673c681ca16a | C8: 9981.27 | D8: 61 | E8: 3.704918 | F8: 0.2295082 | G8: 8.8032787
A9: 8 | B9: 5805de5f2475009eedf62f3b9bfd4341 | C9: 9967.11 | D9: 55 | E9: 3.9818182 | F9: 0.23636364 | G9: 9.3818182
A10: 9 | B10: 2a1dea957904ba6361d5f07ee116f5c8 | C10: 9893.65 | D10: 55 | E10: 3.8363636 | F10: 0.25454545 | G10: 8.7272727
A11: 10 | B11: 7ff411acb259d151dc27023067cb42ed | C11: 9777.02 | D11: 54 | E11: 3.8333333 | F11: 0.18518519 | G11: 9.1111111
A12: 11 | B12: b6cdf2fbe25fb2b09bbe19a3d81cd46d | C12: 9761.17 | D12: 50 | E12: 3.84 | F12: 0.34 | G12: 9.38
A13: 12 | B13: 626bbd5a1d589dcd8954a012fba932bf | C13: 9744.56 | D13: 55 | E13: 3.8545455 | F13: 0.27272727 | G13: 7.8181818
... A21: 20 | B21: 753fe7a770e46081e7eda392e4d1ca67 | C21: 9547.03 | D21: 50 | E21: 3.58 | F21: 0.28 | G21: 9.32
A23: Source: Python ETL output (data/cleaned/*.csv), generated by run_analysis.py from raw Olist-style transactional data.

Sheet Category_Lookup
A1: Category Lookup Tool
A2: Pick a category from the dropdown (yellow cell) to see its live metrics.
A4: Select Category: | B4: computers_accessories
A6: Revenue | B6: =INDEX(Data_Category!$B$2:$B$26,MATCH($B$4,Data_Category!$A$2:$A$26,0)) -> 1685925.4
A7: Total Orders | B7: =INDEX(Data_Category!$C$2:$C$26,MATCH($B$4,Data_Category!$A$2:$A$26,0)) -> 7507
A8: Total Items | B8: =INDEX(Data_Category!$D$2:$D$26,MATCH($B$4,Data_Category!$A$2:$A$26,0)) -> 7589
A9: Avg Price | B9: =INDEX(Data_Category!$E$2:$E$26,MATCH($B$4,Data_Category!$A$2:$A$26,0)) -> 200.76994
A10: Avg Freight | B10: =INDEX(Data_Category!$F$2:$F$26,MATCH($B$4,Data_Category!$A$2:$A$26,0)) -> 21.383892
A11: Avg Review Score | B11: =INDEX(Data_Category!$G$2:$G$26,MATCH($B$4,Data_Category!$A$2:$A$26,0)) -> 3.8348926
A12: Late Delivery Rate | B12: =INDEX(Data_Category!$H$2:$H$26,MATCH($B$4,Data_Category!$A$2:$A$26,0)) -> 0.24232442
A13: Rank by Revenue | B13: =RANK(INDEX(Data_Category!$B$2:$B$26,MATCH($B$4,Data_Category!$A$2:$A$26,0)),Data_Category!$B$2:$B$26) -> 1
A14: % of Total Revenue | B14: =INDEX(Data_Category!$B$2:$B$26,MATCH($B$4,Data_Category!$A$2:$A$26,0))/SUM(Data_Category!$B$2:$B$26) -> 0.094183012
A16: Built with INDEX/MATCH (functional equivalent of XLOOKUP; used instead for wider Excel-version compatibility).

Sheet Seller_Lookup
A1: Seller Lookup Tool
A2: Pick a seller rank (1 = highest revenue) from the dropdown to see that seller's metrics.
A4: Select Seller Rank (1-20): | B4: 1
A6: Seller ID | B6: =INDEX(Data_Sellers!$B$2:$B$21,MATCH($B$4,Data_Sellers!$A$2:$A$21,0)) -> a2ace083ea81f073ff464af92707ad18
A7: Revenue | B7: =INDEX(Data_Sellers!$C$2:$C$21,MATCH($B$4,Data_Sellers!$A$2:$A$21,0)) -> 10890.74
